From 329c0986ebd684091e41679f319bd4788b6bb561 Mon Sep 17 00:00:00 2001
From: eatradish <sakiiily@aosc.io>
Date: Mon, 14 Sep 2020 15:42:07 +0800
Subject: [PATCH] Use syslog.LOG_INFO and LOG_NOTICE instead of LOG_EM

---
 src/pam.py | 15 ++++++++-------
 1 file changed, 8 insertions(+), 7 deletions(-)

diff --git a/src/pam.py b/src/pam.py
index 08cccef..3cf3df2 100644
--- a/src/pam.py
+++ b/src/pam.py
@@ -38,7 +38,8 @@ def doAuth(pamh):
 	if config.getboolean("core", "detection_notice"):
 		pamh.conversation(pamh.Message(pamh.PAM_TEXT_INFO, "Attempting face detection"))
 
-	syslog.syslog(syslog.LOG_INFO, "Attempting facial authentication for user " + pamh.get_user())
+	syslog.syslog(syslog.LOG_INFO | syslog.LOG_AUTH, "Attempting facial authentication for user " + pamh.get_user())
+
 
 	# Run compare as python3 subprocess to circumvent python version and import issues
 	status = subprocess.call(["/usr/bin/python3", os.path.dirname(os.path.abspath(__file__)) + "/compare.py", pamh.get_user()])
@@ -48,26 +49,26 @@ def doAuth(pamh):
 		if not config.getboolean("core", "suppress_unknown"):
 			pamh.conversation(pamh.Message(pamh.PAM_ERROR_MSG, "No face model known"))
 
-		syslog.syslog(syslog.LOG_NOTICE, "Failure, no face model known")
+		syslog.syslog(syslog.LOG_NOTICE | syslog.LOG_AUTH, "Failure, no face model known")
 		syslog.closelog()
 		return pamh.PAM_USER_UNKNOWN
 
 	# Status 11 means we exceded the maximum retry count
 	elif status == 11:
 		pamh.conversation(pamh.Message(pamh.PAM_ERROR_MSG, "Face detection timeout reached"))
-		syslog.syslog(syslog.LOG_INFO, "Failure, timeout reached")
+		syslog.syslog(syslog.LOG_INFO | syslog.LOG_AUTH, "Failure, timeout reached")
 		syslog.closelog()
 		return pamh.PAM_AUTH_ERR
 
 	# Status 12 means we aborted
 	elif status == 12:
-		syslog.syslog(syslog.LOG_INFO, "Failure, general abort")
+		syslog.syslog(syslog.LOG_INFO | syslog.LOG_AUTH, "Failure, general abort")
 		syslog.closelog()
 		return pamh.PAM_AUTH_ERR
 
 	# Status 13 means the image was too dark
 	elif status == 13:
-		syslog.syslog(syslog.LOG_INFO, "Failure, image too dark")
+		syslog.syslog(syslog.LOG_INFO | syslog.LOG_AUTH, "Failure, image too dark")
 		syslog.closelog()
 		pamh.conversation(pamh.Message(pamh.PAM_ERROR_MSG, "Face detection image too dark"))
 		return pamh.PAM_AUTH_ERR
@@ -77,13 +78,13 @@ def doAuth(pamh):
 		if not config.getboolean("core", "no_confirmation"):
 			pamh.conversation(pamh.Message(pamh.PAM_TEXT_INFO, "Identified face as " + pamh.get_user()))
 
-		syslog.syslog(syslog.LOG_INFO, "Login approved")
+		syslog.syslog(syslog.LOG_INFO | syslog.LOG_AUTH, "Login approved")
 		syslog.closelog()
 		return pamh.PAM_SUCCESS
 
 	# Otherwise, we can't discribe what happend but it wasn't successful
 	pamh.conversation(pamh.Message(pamh.PAM_ERROR_MSG, "Unknown error: " + str(status)))
-	syslog.syslog(syslog.LOG_INFO, "Failure, unknown error" + str(status))
+	syslog.syslog(syslog.LOG_INFO | syslog.LOG_AUTH, "Failure, unknown error" + str(status))
 	syslog.closelog()
 	return pamh.PAM_SYSTEM_ERR
 
-- 
2.27.0

